Workbook
Name LIST: Table1[DESCRIPTION2]
Name list: Table1[DESCRIPTION2]

Sheet Table 1
A1: STORE INVENTORY STOCK
A2: S.NO. | B2: MEDICINE | C2: QUANT. | D2: DISPENSED+DATE
A3: CREAMS
A4: 1 | B4: BETADERM (betamethasone) | C4: 4
A5: 2 | B5: Clotrim (Clotrimazole) | C5: 3 | D5: 2 (25-7)
A6: 3 | B6: DAKTARIN GEL (miconazole) | C6: 4
A7: 4 | B7: DEXA-N (dexamethasone + neomycin) | C7: 4
A8: 5 | B8: FUDINAC (Fusidic acid + betamethasone valerate) | C8: 18
A9: 6 | B9: Fusidic-h (Fusidic Acid + Hydrocortisone Acetate) | C9: 0
A10: 7 | B10: KANDEX-N (dexamethasone + neomycin) | C10: 12
A11: 8 | B11: MIDRAZOLE (miconazole) | C11: 34
A12: 9 | B12: MAFDIC (Fusidic acid) | C12: 12
A13: 10 | B13: MAFTRIM (Clotrimazole) | C13: 0
A14: 11 | B14: NOVESTEN (Clotrimazole) | C14: 0
A15: 12 | B15: POLYFAX | C15: 9
A16: 13 | B16: SCABFREE (permethrin) | C16: 5
A17: 14 | B17: SKINFAX | C17: 14
A18: 15 | B18: XYLOAID (lidocaine) | C18: 4
A19: SYRUPS
A20: 1 | B20: ABDO-Z | C20: 6
A21: 2 | B21: AUGMENTIN DS | C21: 56
A22: 3 | B22: AMOXIL 125mg | C22: 50
A23: 4 | B23: AMOXIL 250mg | C23: 50
A24: 5 | B24: CITRALKA | C24: 15 | D24: 2 (25-7)
A25: 6 | B25: ENTAMIZOLE | C25: 28
A26: 7 | B26: FAMIRON | C26: 66
A27: 8 | B27: FAMVID | C27: 90
A28: 9 | B28: IVA | C28: 69
A29: 10 | B29: KRAZE | C29: 50
A30: 11 | B30: MEDIV | C30: 4
A31: 12 | B31: MULTILIFE | C31: 3
A32: 13 | B32: OREXIM | C32: 15
A33: 14 | B33: OREXIM DS | C33: 34
A34: 15 | B34: PARACETMAOL | C34: 3 cartons
A35: 16 | B35: TUSIN | C35: 35
A36: 17 | B36: VELOSEF 125mg | C36: 5 | D36: 2 (25-7)
A37: 18 | B37: VELOSEF 250mg | C37: 5
A38: 19 | B38: ZINKROL | C38: 1 carton
A39: 450ML SYRUPS
A40: 1 | B40: Promethazine | C40: 24
...

Sheet Store
A2: S# | B2: DESCRIPTION | C2: COMPOSITION | D2: TYPE | E2: CATEGORY | F2: QTY
A3: 1 | B3: BETADERM | C3: MICONAZOLE + NEOMYCIN + BETAMETHASONE | D3: CREAM | E3: OPENING | F3: 4
A4: 2 | B4: CLOTRIM | C4: CLOTRIMAZOLE | D4: CREAM | E4: OPENING | F4: 3
A5: 3 | B5: DAKTARIN GEL | C5: MICONAZOLE | D5: GEL | E5: OPENING | F5: 4
A6: 4 | B6: DEXA-N | C6: DEXAMETHASONE + NEOMYCIN | D6: CREAM | E6: OPENING | F6: 4
A7: 5 | B7: FUDINAC | C7: FUSIDIC ACID + BETAMETHASONE VALERATE | D7: CREAM | E7: OPENING | F7: 18
A8: 6 | B8: FUSIDIC-H | C8: FUSIDIC ACID + BETHAMETHASONE VALERATE | D8: CREAM | E8: OPENING | F8: 0
A9: 7 | B9: GENTICYN | C9: GENTAMICIN | D9: CREAM | E9: OPENING | F9: 1
A10: 8 | B10: KANDEX-N | C10: DEXAMETHASONE + NEOMYCIN | D10: CREAM | E10: OPENING | F10: 12
A11: 9 | B11: MIDRAZOLE | C11: MICONAZOLE | D11: CREAM | E11: OPENING | F11: 34
A12: 10 | B12: MAFDIC | C12: FUSIDIC ACID | D12: CREAM | E12: OPENING | F12: 12
A13: 11 | B13: MAFTRIM | C13: CLOTRIMAZOLE | D13: CREAM | E13: OPENING | F13: 1
A14: 12 | B14: NOVESTEN | C14: CLOTRIMAZOLE | D14: CREAM | E14: OPENING | F14: 1
... A125: 123 | B125: COOVER 400MG | C125: CEFIXIME | D125: TABLET | E125: OPENING | F125: 19
A126: 124 | B126: DAFLON 500MG | C126: MICRONIAZID, PURIFIED FLAVONOID FRACTION | D126: TABLET | E126: OPENING
A127: 125 | B127: SAFEPRAM 10MG | C127: ESCITALOPRAM | D127: TABLET | E127: OPENING
A128: 126 | B128: COLDREX | C128: PARACETAMOL, DETROMETHORPHAN, CHLORPHENIRAMINE | D128: TABLET | E128: OPENING
A129: 127 | B129: AMLIS 10 MG | C129: AMLODIPINE BESYLATE | D129: TABLET | E129: OPENING
A130: 128 | B130: FEXOFAX 60MG | C130: FEXOFENADINE | D130: TABLET | E130: OPENING
A131: 129 | B131: ORTIZIN 10MG | C131: CETIRIZINE DIHYDROCHLORIDE | D131: TABLET | E131: OPENING | F131: 13
A132: 130 | B132: NEUROBION | C132: VIT B1, B6, B12 | D132: CAPSULE | E132: OPENING | F132: 3
A133: 131 | B133: MECOBALAMINE | C133: MECOBALAMINE | D133: CAPSULE | E133: OPENING | F133: 26
A134: 132 | B134: SANGOBION | C134: IRON + B COMPLEX | D134: CAPSULE | E134: OPENING | F134: 1
A135: 133 | B135: COZOLE | C135: FLUCONAZOLE | D135: CAPSULE | E135: OPENING | F135: 8
A136: 134 | B136: LINK-D | C136: VITAMIN D | D136: CAPSULE | E136: OPENING | F136: 36
A137: 135 | B137: LOPIUM | C137: LOPERAMIDE | D137: CAPSULE | E137: OPENING | F137: 32
A138: 136 | B138: FEFOL VIT | C138: IRON + VITAMINS + FOLIC ACID | D138: CAPSULE | E138: OPENING | F138: 4
A139: 137 | B139: ILARIO | C139: DULOXETINE | D139: CAPSULE | E139: OPENING | F139: 30
A140: 138 | B140: CLAMENTIN DS | C140: CO-AMOXICLAV | D140: CAPSULE | E140: OPENING | F140: 6
A141: 139 | B141: NOVOMAX 500MG | C141: AMOXICILLIN | D141: CAPSULE | E141: OPENING | F141: 1
A142: 140 | B142: AMOXYCILLIN 250MG | C142: AMOXICILLIN | D142: CAPSULE | E142: OPENING | F142: 10
... A173: 171 | B173: TRANSAMIN | C173: TRANEXAMIC ACID | D173: INJECTION | E173: OPENING | F173: 0
A174: 172

Sheet Stock register
A1: S # | B1: DESCRIPTION2 | C1: COMPOSITION | D1: TYPE | E1: UOM | F1: OPENING | G1: RECEIPT | H1: ISSUANCE | I1: BALANCE
A2: 1 | B2: BETADERM | C2: MICONAZOLE + NEOMYCIN + BETAMETHASONE | D2: CREAM | E2: BOX | F2: 4 | G2: =SUMIFS(TRANSACTION!D:D,TRANSACTION!C:C,Table1[[#This Row],[DESCRIPTION2]]) -> 20 | H2: =SUMIFS(TRANSACTION!$E:$E,TRANSACTION!$C:$C,Table1[[#This Row],[DESCRIPTION2]]) -> 24 | I2: =Table1[[#This Row],[OPENING]]+Table1[[#This Row],[RECEIPT]]-Table1[[#This Row],[ISSUANCE]] -> 0
A3: =IF(Table1[[#This Row],[DESCRIPTION2]]="","",A2+1) -> 2 | B3: CLOTRIM | C3: CLOTRIMAZOLE | D3: CREAM | E3: BOX | F3: 1 | G3: =SUMIFS(TRANSACTION!D:D,TRANSACTION!C:C,Table1[[#This Row],[DESCRIPTION2]]) -> 0 | H3: =SUMIFS(TRANSACTION!$E:$E,TRANSACTION!$C:$C,Table1[[#This Row],[DESCRIPTION2]]) -> 1 | I3: =Table1[[#This Row],[OPENING]]+Table1[[#This Row],[RECEIPT]]-Table1[[#This Row],[ISSUANCE]] -> 0
A4: =IF(Table1[[#This Row],[DESCRIPTION2]]="","",A3+1) -> 3 | B4: DAKTARIN GEL | C4: MICONAZOLE | D4: GEL | E4: BOX | F4: 4 | G4: =SUMIFS(TRANSACTION!D:D,TRANSACTION!C:C,Table1[[#This Row],[DESCRIPTION2]]) -> 0 | H4: =SUMIFS(TRANSACTION!$E:$E,TRANSACTION!$C:$C,Table1[[#This Row],[DESCRIPTION2]]) -> 4 | I4: =Table1[[#This Row],[OPENING]]+Table1[[#This Row],[RECEIPT]]-Table1[[#This Row],[ISSUANCE]] -> 0
A5: =IF(Table1[[#This Row],[DESCRIPTION2]]="","",A4+1) -> 4 | B5: DEXA-N | C5: DEXAMETHASONE + NEOMYCIN | D5: CREAM | E5: BOX | F5: 5 | G5: =SUMIFS(TRANSACTION!D:D,TRANSACTION!C:C,Table1[[#This Row],[DESCRIPTION2]]) -> 24 | H5: =SUMIFS(TRANSACTION!$E:$E,TRANSACTION!$C:$C,Table1[[#This Row],[DESCRIPTION2]]) -> 15 | I5: =Table1[[#This Row],[OPENING]]+Table1[[#This Row],[RECEIPT]]-Table1[[#This Row],[ISSUANCE]] -> 14
A6: =IF(Table1[[#This Row],[DESCRIPTION2]]="","",A5+1) -> 5 | B6: FUDINAG | C6: FUSIDIC ACID | D6: CREAM | E6: BOX | F6: 17 | G6: =SUMIFS(TRANSACTION!D:D,TRANSACTION!C:C,Table1[[#This Row],[DESCRIPTION2]]) -> 0 | H6: =SUMIFS(TRANSACTION!$E:$E,TRANSACTION!$C:$C,Table1[[#This Row],[DESCRIPTION2]]) -> 17 | I6: =Table1[[#This Row],[OPENING]]+Table1[[#This Row],[RECEIPT]]-Table1[[#This Row],[ISSUANCE]] -> 0
A7: =IF(Table1[[#This Row],[DESCRIPTION2]]="","",A6+1) -> 6 | B7: FUSIDIC-H | C7: FUSIDIC ACID + BETHAMETHASONE VALERATE | D7: CREAM | E7: BOX | F7: 0 | G7: =SUMIFS(TRANSACTION!D:D,TRANSACTION!C:C,Table1[[#This Row],[DESCRIPTION2]]) -> 0 | H7: =SUMIFS(TRANSACTION!$E:$E,TRANSACTION!$C:$C,Table1[[#This Row],[DESCRIPTION2]]) -> 0 | I7: =Table1[[#This Row],[OPENING]]+Table1[[#This Row],[RECEIPT]]-Table1[[#This Row],[ISSUANCE]] -> 0
A8: =IF(Table1[[#This Row],[DESCRIPTION2]]="","",A7+1) -> 7 | B8: GENTICYN | C8: GENTAMICIN | D8: CREAM | E8: BOX | F8: 2 | G8: =SUMIFS(TRANSACTION!D:D,TRANSACTION!C:C,Table1[[#This Row],[DESCRIPTION2]]) -> 60 | H8: =SUMIFS(TRANSACTION!$E:$E,TRANSACTION!$C:$C,Table1[[#This Row],[DESCRIPTION2]]) -> 18 | I8: =Table1[[#This Row],[OPENING]]+Table1[[#This Row],[RECEIPT]]-Table1[[#This Row],[ISSUANCE]] -> 44
A9: =IF(Table1[[#This Row],[DESCRIPTION2]]="","",A8+1) -> 8 | B9: KANADEX-N | C9: DEXAMETHASONE + NEOMYCIN | D9: CREAM | E9: BOX | F9: 12 | G9: =SUMIFS(TRANSACTION!D:D,TRANSACTION!C:C,Table1[[#This Row],[DESCRIPTION2]]) -> 0 | H9: =SUMIFS(TRANSACTION!$E:$E,TRANSACTION!$C:$C,Table1[[#This Row],[DESCRIPTION2]]) -> 12 | I9: =Table1[[#This Row],[OPENING]]+Table1[[#This Row],[RECEIPT]]-Table1[[#This Row],[ISSUANCE]] -> 0
A10: =IF(Table1[[#This Row],[DESCRIPTION2]]="","",A9+1) -> 9 | B10: MIDROZOLE ORAL GEL | C10: MICONAZOLE | D10: CREAM | E10: BOX | F10: 34 | G10: =SUMIFS(TRANSACTION!D:D,TRANSACTION!C:C,Table1[[#This Row],[DESCRIPTION2]]) -> 60 | H10: =SUMIFS(TRANSACTION!$E:$E,TRANSACTION!$C:$C,Table1[[#This Row],[DESCRIPTION2]]) -> 51 | I10: =Table1[[#This Row],[OPENING]]+Table1[[#This Row],[RECEIPT]]-Table1[[#This Row],[ISSUANCE]] -> 43
A11: =IF(Table1[[#This Row],[DESCRIPTION2]]="","",A10+1) -> 10 | B11: MAFDIC | C11: FUSIDIC ACID | D11: CREAM | E11: BOX | F11: 12 | G11: =SUMIFS(TRANSACTION!D:D,TRANSACTION!C:C,Table1[[#This Row],[DESCRIPTION2]]) -> 0 | H11: =SUMIFS(TRANSACTION!$E:$E,TRANSACTION!$C:$C,Table1[[#This Row],[DESCRIPTION2]]) -> 12 | I11: =Table1[[#This Row],[OPENING]]+Table1[[#This Row],[RECEIPT]]-Table1[[#This Row],[ISSUANCE]] -> 0
A12: =IF(Table1[[#This Row],[DESCRIPTION2]]="","",A11+1) -> 11 | B12: MAFTRIM | C12: CLOTRIMAZOLE | D12: CREAM | E12: BOX | F12: 1 | G12: =SUMIFS(TRANSACTION!D:D,TRANSACTION!C:C,Table1[[#This Row],[DESCRIPTION2]]) -> 0 | H12: =SUMIFS(TRANSACTION!$E:$E,TRANSACTION!$C:$C,Table1[[#This Row],[DESCRIPTION2]]) -> 1 | I12: =Table1[[#This Row],[OPENING]]+Table1[[#This Row],[RECEIPT]]-Table1[[#This Row],[ISSUANCE]] -> 0
A13: =IF(Table1[[#This Row],[DESCRIPTION2]]="","",A12+1) -> 12 | B13: NOVESTEN | C13: CLOTRIMAZOLE | D13: CREAM | E13: BOX | F13: 1 | G13: =SUMIFS(TRANSACTION!D:D,TRANSACTION!C:C,Table1[[#This Row],[DESCRIPTION2]]) -> 0 | H13: =SUMIFS(TRANSACTION!$E:$E,TRANSACTION!$C:$C,Table1[[#This Row],[DESCRIPTION2]]) -> 1 | I13: =Table1[[#This Row],[OPENING]]+Table1[[#This Row],[RECEIPT]]-Table1[[#This Row],[ISSUANCE]] -> 0
A14: =IF(Table1[[#This Row],[DESCRIPTION2]]="","",A13+1) -> 13 | B14: POLYFAX | C14: POLYFAX | D14: CREAM | E14: BOX | F14: 9 | G14: =SUMIFS(TRANSACTION!D:D,TRANSACTION!C:C,Table1[[#This Row],[DESCRIPTION2]]) -> 0 | H14: =SUMIFS(TRANSACTION!$E:$E,TRANSACTION!$C:$C,Table1[[#This Row],[DESCRIPTION2]]) -> 4 | I14: =Table1[[#This Row],[OPENING]]+Table1[[#This Row],[RECEIPT]]-Table1[[#This Row],[ISSUANCE]] -> 5
... A30: =IF(Table1[[#This Row],[DESCRIPTION2]]="","",A29+1) -> 29 | B30: OREXIM | C30: CEFIXIME | D30: SYRUP | E30: BOX | F30: 15 | G30: =SUMIFS(TRANSACTION!D:D,TRANSACTION!C:C,Table1[[#This Row],[DESCRIPTION2]]) -> 2 | H30: =SUMIFS(TRANSACTION!$E:$E,TRANSACTION!$C:$C,Table1[[#This Row],[DESCRIPTION2]]) -> 17 | I30: =Table1[[#This Row],[OPENING]]+Table1[[#This Row],[RECEIPT]]-Table1[[#This Row],[ISSUANCE]] -> 0
A31: =IF(Table1[[#This Row],[DESCRIPTION2]]="","",A30+1) -> 30 | B31: OREXIM DS | C31: CEFIXIME | D31: SYRUP | E31: BOX | F31: 34 | G31: =SUMIFS(TRANSACTION!D:D,TRANSACTION!C:C,Table1[[#This Row],[DESCRIPTION2]]) -> 1 | H31: =SUMIFS(TRANSACTION!$E:$E,TRANSACTION!$C:$C,Table1[[#This Row],[DESCRIPTION2]]) -> 35 | I31: =Table1[[#This Row],[OPENING]]+Table1[[#This Row],[RECEIPT]]-Table1[[#This Row],[ISSUANCE]] -> 0 | K31: EXP: 04/26
A32: =IF(Table1[[#This Row],[DESCRIPTION2]]="","",A31+1) -> 31 | B32: PARACETAMOL SYRUP | C32: PARACETAMOL | D32: SYRUP | E32: BOX | F32: 450 | G32: =SUMIFS(TRANSACTION!D:D,TRANSACTION!C:C,Table1[[#This Row],[DESCRIPTION2]]) -> 0 | H32: =SUMIFS(TRANSACTION!$E:$E,TRANSACTION!$C:$C,Table1[[#This Row],[DESCRIPTION2]]) -> 450 | I32: =Table1[[#This Row],[OPENING]]+Table1[[#This Row],[RECEIPT]]-Table1[[#This Row],[ISSUANCE]] -> 0
A33: =IF(Table1[[#This Row],[DESCRIPTION2]]="","",A32+1) -> 32 | B33: TUSIN | C33: IVY LEAF EXTRACT | D33: SYRUP | E33: BOX | F33: 40 | G33: =SUMIFS(TRANSACTION!D:D,TRANSACTION!C:C,Table1[[#This Row],[DESCRIPTION2]]) -> 0 | H33: =SUMIFS(TRANSACTION!$E:$E,TRANSACTION!$C:$C,Table1[[#This Row],[DESCRIPTION2]]) -> 40 | I33: =Table1[[#This Row],[OPENING]]+Table1[[#This Row],[RECEIPT]]-Table1[[#This Row],[ISSUANCE]] -> 0
A34: =IF(Table1[[#This Row],[DESCRIPTION2]]="","",A33+1) -> 33 | B34: VELOSEF 125mg | C34: CEPHRADINE | D34: SYRUP | E34: BOX | F34: 5 | G34: =SUMIFS(TRANSACTION!D:D,TRANSACTION!C:C,Table1[[#This Row],[DESCRIPTION2]]) -> 0 | H34: =SUMIFS(TRANSACTION!$E:$E,TRANSACTION!$C:$C,Table1[[#This Row],[DESCRIPTION2]]) -> 5 | I34: =Table1[[#This Row],[OPENING]]+Table1[[#This Row],[RECEIPT]]-Table1[[#This Row],[ISSUANCE]] -> 0
A35: =IF(Table1[[#This Row],[DESCRIPTION2]]="","",A34+1) -> 34 | B35: VELOSEF 250mg | C35: CEPHRADINE | D35: SYRUP | E35: BOX | F35: 1 | G35: =SUMIFS(TRANSACTION!D:D,TRANSACTION!C:C,Table1[[#This Row],[DESCRIPTION2]]) -> 0 | H35: =SUMIFS(TRANSACTION!$E:$E,TRANSACTION!$C:$C,Table1[[#This Row],[DESCRIPTION2]]) -> 1 | I35: =Table1[[#This Row],[OPENING]]+Table1[[#This Row],[RECEIPT]]-Table1[[#This Row],[ISSUANCE]] -> 0
A36: =IF(Table1[[#This Row],[DESCRIPTION2]]="","",A35+1) -> 35 | B36: ZINKROL | C36: ZINC SULPHATE MONOHYDRATE | D36: SYRUP | E36: BOX | F36: 320 | G36: =SUMIFS(TRANSACTION!D:D,TRANSACTION!C:C,Table1[[#This Row],[DESCRIPTION2]]) -> 0 | H36: =SUMIFS(TRANSACTION!$E:$E,TRANSACTION!$C:$C,Table1[[#This Row],[DESCRIPTION2]]) -> 195 | I36: =Table1[[#This Row],[OPENING]]+Table1[[#This Row],[RECEIPT]]-Table1[[#This Row],[ISSUANCE]] -> 125
A37: =IF(Table1[[#This Row],[DESCRIPTION2]]="","",A36+1) -> 36 | B37: PROMETHAZINE | C37: PROMETHAZINE HYDROCHLORIDE | D37: SYRUP | E37: BOX | F37: 22 | G37: =SUMIFS(TRANSACTION!D:D,TRANSACTION!C:C,Table1[[#This Row],[DESCRIPTION2]]) -> 0 | H37: =SUMIFS(TRANSACTION!$E:$E,TRANSACTION!$C:$C,Table1[[#This Row],[DESCRIPTION2]]) -> 22 | I37: =Table1[[#This Row],[OPENING]]+Table1[[#This Row],[RECEIPT]]-Table1[[#This Row],[ISSUANCE]] -> 0 | K37: EXP: 03/26
A38: =IF(Table1[[#This Row],[DESCRIPTION2]]="","",A37+1) -> 37 | B38: COLIC | C38: CARMINATIVE MIXTURE | D38: SYRUP | E38: BOX | F38: 9 | G38: =SUMIFS(TRANSACTION!D:D,TRANSACTION!C:C,Table1[[#This Row],[DESCRIPTION2]]) -> 0 | H38: =SUMIFS(TRANSACTION!$E:$E,TRANSACTION!$C:$C,Table1[[#This Row],[DESCRIPTION2]]) -> 9 | I38: =Table1[[#This Row],[OPENING]]+Table1[[#This Row],[RECEIPT]]-Table1[[#This Row],[ISSUANCE]] -> 0
A39: =IF(Table1[[#This Row],[DESCRIPTION2]]="","",A38+1) -> 38 | B39: SAMODRYL | C39: AMMONIUM CHLORIDE | D39: SYRUP | E39: BOX | F39: 20 | G39: =SUMIFS(TRANSACTION!D:D,TRANSACTION!C:C,Table1[[#This Row],[DESCRIPTION2]]) -> 80 | H39: =SUMIFS(TRANSACTION!$E:$E,TRANSACTION!$C:$C,Table1[[#This Row],[DESCRIPTION2]]) -> 79 | I39: =Table1[[#This Row],[OPENING]]+Table1[[#This Row],[RECEIPT]]-Table1[[#This Row],[ISSUANCE]] -> 21
A40: =IF(Table1[[#This Row],[DESCRIPTION2]]="","",A39+1) -> 39 | B40: BINIPLEX | C40: B-COMPLEX | D40: SYRUP | E40: BOX | F40: 40 | G40: =SUMIFS(TRANSACTION!D:D,TRANSACTION!C:C,Table1[[#This Row],[DESCRIPTION2]]) -> 0 | H40: =SUMIFS(TRANSACTION!$E:$E,TRANSACTION!$C:$C,Table1[[#This Row],[DESCRIPTION2]]) -> 40 | I40: =Table1[[#This Row],[OPENING]]+Table1[[#This Row],[RECEIPT]]-Table1[[#This Row],[ISSUANCE]] -> 0
A41: =IF(Table1[[#This Row],[DESCRIPTION2]]="","",A40+1) -> 40 | B41: REGOPLEX | C41: B-COMPLEX | D41: SYRUP | E41: BOX | F41: 25 | G41: =SUMIFS(TRANSACTION!D:D,TRANSACTION!C:C,Table1[[#This Row],[DESCRIPTION2]]) -> 0 | H41: =SUMIFS(TRANSACTION!$E:$E,TRANSACTION!$C:$C,Table1[[#This Row],[DESCRIPTION2]]) -> 25 | I41: =Table1[[#This Row],[OPENING]]+Table1[[#This Row],[RECEIPT]]-Table1[[#This Row],[ISSUANCE]] -> 0 | K41: EXP: 08/26
A42: =IF(Table1[[#This Row],[DESCRIPTION2]]="","",A41+1) -> 41 | B42: CHLORAMINE | C42: CHLORPHENIRAMINE MALEATE | D42: SYRUP | E42: BOX | F42: 22 | G42: =SUMIFS(TRANSACTION!D:D,TRANSACTION!C:C,Table1[[#This Row],[DESCRIPTION2]]) -> 50 | H42: =SUMIFS(TRANSACTION!$E:$E,TRANSACTION!$C:$C,Table1[[#This Row],[DESCRIPTION2]]) -> 40 | I42: =Table1[[#This Row],[OPENING]]+Table1[[#This Row],[RECEIPT]]-Table1[[#This Row],[ISSUANCE]] -> 32
A43: =IF(Table1[[#This Row],[DESCRIPTION2]]="","",A42+1) -> 42 | B43: SEMOSIL | C43: Al HYDROXIDE, Mg HYDROXIDE + SIMETHICONE | D43: SYRUP | E43: BOX | F43: 4 | G43: =SUMIFS(TRANSACTION!D:D,TRANSACTION!C:C,Table1[[#This Row],[DESCRIPTION2]]) -> 74 | H43: =SUMIFS(TRANSACTION!$E:$E,TRANSACTION!$C:$C,Table1[[#This Row],[DESCRIPTION2]]) -> 35 | I43: =Table1[[#This Row],[OPENING]]+Table1[[#This Row],[RECEIPT]]-Table1[[#This Row],[ISSUANCE]] -> 43
A44: =IF(Table1[[#This Row],[DESCRIPTION2]]="","",A43+1) -> 43 | B44: URAL | C44: SODIUM ACID CITRATE | D44: SYRUP | E44: BOX | F44: 29 | G44: =SUMIFS(TRANSACTION!D:D,TRANSACTION!C:C,Table1[[#This Row],[DESCRIPTION2]]) -> 0 | H44: =SUMIFS(TRANSACTION!$E:$E,TRANSACTION!$C:$C,Table1[[#This Row],[DESCRIPTION2]]) -> 26 | I44: =Table1[[#This Row],[OPENING]]+Table1[[#This Row],[RECEIPT]]-Table1[[#This Row],[ISSUANCE]] -> 3 | K44: EXP: 08/26
A45: =IF(Table1[[#This Row],[DESCRIPTION2]]="","",A44+1) -> 44 | B45: NOVOGEL | C45: ALUMINIA MAGNESIC SUSPENSION | D45: SYRUP | E45: BOX | F45: 0 | G45: =SUMIFS(TRANSACTION!D:D,TRANSACTION!C:C,Table1[[#This Row],[DESCRIPTION2]]) -> 0 | H45: =SUMIFS(TRANSACTION!$E:$E,TRANSACTION!$C:$C,Table1[[#This Row],[DESCRIPTION2]]) -> 0 | I45: =Table1[[#This Row],[OPENING]]+Table1[[#This Row],[RECEIPT]]-Table1[[#This Row],[ISSUANCE]] -> 0
A46: =IF(Table1[[#This Row],[DESCRIPTION2]]="","",A45+1) -> 45 | B46: METROZYL | C46: ALUMINIA MAGNESIC SUSPENSION | D46: SYRUP | E46: BOX | F46: 0 | G46: =SUMIFS(TRANSACTION!D:D,TRANSACTION!C:C,Table1[[#This Row],[DESCRIPTION2]]) -> 0 | H46: =SUMIFS(TRANSACTION!$E:$E,TRANSACTION!$C:$C,Table1[[#This Row],[DESCRIPTION2]]) -> 0 | I46: =Table1[[#This Row],[OPENING]]+Table1[[#This Row],[RECEIPT]]-Table1[[#This Row],[ISSUANCE]] -> 0
A47: =IF(Table1[[#This Row],[DESCRIPTION2]]="","",A46+1) -> 46 | B47: MYO-INOSITOL | C47: D-CHIRO-INISITOL + FOLIC ACID | D47: SACHET | E47: BOX | F47: 9 | G47: =SUMIFS(TRANSACTION!D:D,TRANSACTION!C:C,Table1[[#This Row],[DESCRIPTION2]]) -> 0 | H47: =SUMIFS(TRANSACTION!$E:$E,TRANSACTION!$C:$C,Table1[[#This Row],[DESCRIPTION2]]) -> 9 | I47: =Table1[[#This Row],[OPENING]]+Table1[[#This Row],[RECEIPT]]-Table1[[#This Row],[ISSUANCE]] -> 0
A48: =IF(Table1[[#This Row],[DESCRIPTION2]]="","",A47+1) -> 47 | B48: CAL CEE | C48: CALCIUM 1000 | D48: SACHET | E48: BOX | F48: 10 | G48: =SUMIFS(TRANSACTION!D:D,TRANSACTION!C:C,Table1[[#This Row],[DESCRIPTION2]]) -> 238 | H48: =SUMIFS(TRANSACTION!$E:$E,TRANSACTION!$C:$C,Table1[[#This Row],[DESCRIPTION2]]) -> 222 | I48: =Table1[[#This Row],[OPENING]]+Table1[[#This Row],[RECEIPT]]-Table1[[#This Row],[ISSUANCE]] -> 26
A49: =IF(Table1[[#This Row],[DESCRIPTION2]]="","",A48+1) -> 48 | B49: CRANMAC | C49: CRANBERRY | D49: SACHET | E49: BOX | F49: 5 | G49: =SUMIFS(TRANSACTION!D:D,TRANSACTION!C:C,Table1[[#This Row],[DESCRIPTION2]]) -> 6 | H49: =SUMIFS(TRANSACTION!$E:$E,TRANSACTION!$C:$C,Table1[[#This Row],[DESCRIPTION2]]) -> 11 | I49: =Table1[[#This Row],[OPENING]]+Table1[[#This Row],[RECEIPT]]-Table1[[#This Row],[ISSUANCE]] -> 0
A50: =IF(Table1[[#This Row],[DESCRIPTION2]]="","",A49+1) -> 49 | B50: ZETALUKAST | C50: MONTELUKAST | D50: SACHET | E50: BOX | F50: 8 | G50: =SUMIFS(TRANSACTION!D:D,TRANSACTION!C:C,Table1[[#This Row],[DESCRIPTION2]]) -> 70 | H50: =SUMIFS(TRANSACTION!$E:$E,TRANSACTION!$C:$C,Table1[[#This Row],[DESCRIPTION2]]) -> 41 | I50: =Table1[[#This Row],[OPENING]]+Table1[[#This Row],[RECEIPT]]-Table1[[#This Row],[ISSUANCE]] -> 37
A51: =IF(Table1[[#This Row],[DESCRIPTION2]]="","",A50+1) -> 50 | B51: ORS | C51: LOW OSMOLAR ORS | D51: SACHET | E51: BOX | F51: 48 | G51: =SUMIFS(TRANSACTION!D:D,TRANSACTION!C:C,Table1[[#This Row],[DESCRIPTION2]]) -> 0 | H51: =SUMIFS(TRANSACTION!$E:$E,TRANSACTION!$C:$C,Table1[[#This Row],[DESCRIPTION2]]) -> 40 | I51: =Table1[[#This Row],[OPENING]]+Table1[[#This Row],[RECEIPT]]-Table1[[#This Row],[ISSUANCE]] -> 8 | K51: EXP: 10/26
A52: =IF(Table1[[#This Row],[DESCRIPTION2]]="","",A51+1) -> 51 | B52: EFZOCAL-C | C52: CALCIUM + VIT C | D52: SACHET | E52: BOX | F52: 1 | G52: =SUMIFS(TRANSACTION!D:D,TRANSACTION!C:C,Table1[[#This Row],[DESCRIPTION2]]) -> 0 | H52: =SUMIFS(TRANSACTION!$E:$E,TRANSACTION!$C:$C,Table1[[#This Row],[DESCRIPTION2]]) -> 1 | I52: =Table1[[#This Row],[OPENING]]+Table1[[#This Row],[RECEIPT]]-Table1[[#This Row],[ISSUANCE]] -> 0
A53: =IF(Table1[[#This Row],[DESCRIPTION2]]="","",A52+1) -> 52 | B53: BLINK FRESH | C53: POLYVINYL ALCOLOHOL + POVIDONE | D53: EYE DROP | E53: BOX | F53: 17 | G53: =SUMIFS(TRANSACTION!D:D,TRANSACTION!C:C,Table1[[#This Row],[DESCRIPTION2]]) -> 10 | H53: =SUMIFS(TRANSACTION!$E:$E,TRANSACTION!$C:$C,Table1[[#This Row],[DESCRIPTION2]]) -> 17 | I53: =Table1[[#This Row],[OPENING]]+Table1[[#This Row],[RECEIPT]]-Table1[[#This Row],[ISSUANCE]] -> 10
A54: =IF(Table1[[#This Row],[DESCRIPTION2]]="","",A53+1) -> 53 | B54: BFL | C54: FLOUROMETHOLONE | D54: EYE DROP | E54: BOX | F54: 6 | G54: =SUMIFS(TRANSACTION!D:D,TRANSACTION!C:C,Table1[[#This Row],[DESCRIPTION2]]) -> 22 | H54: =SUMIFS(TRANSACTION!$E:$E,TRANSACTION!$C:$C,Table1[[#This Row],[DESCRIPTION2]]) -> 8 | I54: =Table1[[#This Row],[OPENING]]+Table1[[#This Row],[RECEIPT]]-Table1[[#This Row],[ISSUANCE]] -> 20
A55: =IF(Table1[[#This Row],[DESCRIPTION2]]="","",A54+1) -> 54 | B55: OPTITEK 0.3% | C55: TOBRAMYCIN | D55: EYE DROP | E55: BOX | F55: 10 | G55: =SUMIFS(TRANSACTION!D:D,TRANSACTION!C:C,Table1[[#This Row],[DESCRIPTION2]]) -> 0 | H55: =SUMIFS(TRANSACTION!$E:$E,TRANSACTION!$C:$C,Table1[[#This Row],[DESCRIPTION2]]) -> 10 | I55: =Table1[[#This Row],[OPENING]]+Table1[[#This Row],[RECEIPT]]-Table1[[#This Row],[ISSUANCE]] -> 0
...

Sheet TRANSACTION
B2: DATE | C2: ITEM | D2: RECEIPT | E2: ISSUANCE | F2: REMARKS
B3: 45869 | C3: BETADERM
B4: 45869 | C4: CLOTRIM
B5: 45869 | C5: DAKTARIN GEL
B6: 45869 | C6: DEXA-N
B7: 45869 | C7: FUDINAG
B8: 45869 | C8: FUSIDIC-H
B9: 45869 | C9: GENTICYN
B10: 45869 | C10: KANADEX-N
B11: 45869 | C11: MIDROZOLE ORAL GEL
B12: 45869 | C12: MAFDIC
B13: 45869 | C13: MAFTRIM
B14: 45869 | C14: NOVESTEN
... B334: 46119 | C334: FEVEREN
B352: 45870 | C352: AMROPLEX | E352: 1
B353: 45870 | C353: COZOLE | E353: 8
B354: 45870 | C354: NEUROBION | E354: 1
B355: 45870 | C355: ATENOPHARM 50MG | E355: 5
B356: 45870 | C356: AMCOBAL | E356: 1
B357: 45870 | C357: CRANMAC | E357: 2
B358: 45870 | C358: EFZOCAL-C | E358: 1
B359: 45870 | C359: FEFOL VIT | E359: 2
B360: 45870 | C360: ADICOVIL | E360: 1
B361: 45870 | C361: TREMOMED | E361: 2
B362: 45870 | C362: ELINGTON | E362: 2
B363: 45870 | C363: P-ORPH | E363: 2
... B383: 45875 | C383: FLUSAID | E383: 1
B384: 45875 | C384: BFL | D384: 2 | F384: FOUND OLD STOCK
B385: 45875 | C385: MULTILIFE | E385: 3 | F385: STOCK CLEARANCE
B386: 45876 | C386: XIMBACT 400MG | E386: 5
B387: 45876 | C387: ALDRON | E387: 2
B388: 45876 | C388: BEFLAM | E388: 1
B389: 45876 | C389: LORGY 10MG | E389: 2
B390: 45876 | C390: LORGY D | E390: 2
B391: 45876 | C391: FAMVID | E391: 6
B392: 45876 | C392: COZOLE | E392: 1
B393: 45876 | C393: CRANMAC | E393: 3
B394: 45876 | C394: LINK-D | E394: 7
B395: 45877 | C395: Z-CIPRO 500MG | E395: 3
B396: 45878 | C396: PARACETAMOL SYRUP | E396: 7
...

Sheet Pharmacy
A2: S# | B2: DESCRIPTION | C2: COMPOSITION | D2: TYPE | E2: CATEGORY | F2: QTY
A3: 1 | B3: BETADERM | C3: MICONAZOLE + NEOMYCIN + BETAMETHASONE | D3: CREAM | E3: OPENING
A4: 2 | B4: CLOTRIM | C4: CLOTRIMAZOLE | D4: CREAM | E4: OPENING
A5: 3 | B5: DAKTARIN GEL | C5: MICONAZOLE | D5: GEL | E5: OPENING
A6: 4 | B6: DEXA-N | C6: DEXAMETHASONE + NEOMYCIN | D6: CREAM | E6: OPENING
A7: 5 | B7: FUDINAC | C7: FUSIDIC ACID + BETAMETHASONE VALERATE | D7: CREAM | E7: OPENING
A8: 6 | B8: FUSIDIC-H | C8: FUSIDIC ACID + BETHAMETHASONE VALERATE | D8: CREAM | E8: OPENING | F8: 0
A9: 7 | B9: GENTICYN | C9: GENTAMICIN | D9: CREAM | E9: OPENING
A10: 8 | B10: KANDEX-N | C10: DEXAMETHASONE + NEOMYCIN | D10: CREAM | E10: OPENING
A11: 9 | B11: MIDRAZOLE | C11: MICONAZOLE | D11: CREAM | E11: OPENING
A12: 10 | B12: MAFDIC | C12: FUSIDIC ACID | D12: CREAM | E12: OPENING
A13: 11 | B13: MAFTRIM | C13: CLOTRIMAZOLE | D13: CREAM | E13: OPENING
A14: 12 | B14: NOVESTEN | C14: CLOTRIMAZOLE | D14: CREAM | E14: OPENING
A15: 13 | B15: POLYFAX | C15: POLYFAX | D15: CREAM | E15: OPENING
A16: 14 | B16: SCABFREE | C16: PERMETHRIN | D16: CREAM | E16: OPENING
A17: 15 | B17: SKINFAX | C17: SKINFAX | D17: CREAM | E17: OPENING
A18: 16 | B18: XYLOAID | C18: LIDOCAINE | D18: CREAM | E18: OPENING
A19: 17 | B19: ABDO-Z | C19: ANTIDIARRHEAL + ZINC | D19: SYRUP | E19: OPENING
A20: 18 | B20: AUGMENTIN DS | C20: CO-AMOXICLAV | D20: SYRUP | E20: OPENING
... A173: 171 | B173: TRANSAMIN | C173: TRANEXAMIC ACID | D173: INJECTION | E173: OPENING
A174: 172
A175: 173
A176: 174
A177: 175
A178: 176
A179: 177
A180: 178
